Workbook

Sheet README
A1: Batch 1 - Danalieth (niveau 59)
A2: Premier lot de contenu : tout ce que Danalieth utilise, au format d'import du catalogue.
A4: Onglets
A5: Entities : une ligne par élément du catalogue (classe, don, pouvoir, sort, objet, archétype...).
A6: Effects : un effet par ligne, rattaché à une entité par entity_id (modèle du moteur de règles).
A7: Progressions : une ligne par niveau de classe (BBA, sauvegardes, ce que le niveau donne).
A8: Relations : liens entre entités (donne, propriété d'objet, liste de sorts...).
A9: Danalieth checks : les 8 totaux de la fiche, recalculés à partir des composantes. Doivent rester à « OK ».
A10: Questions : ce que je n'ai pas pu déduire. Répondez dans la colonne jaune.
A12: Comment relire
A13: 1. Colonne status : draft = rempli par Claude, à relire ; to confirm = hypothèse à valider ; to complete = information manquante ; reviewed = validé par vous.
A14: 2. Cellules jaunes = à compléter ou confirmer en priorité.
... A23: Textes des livres hors SRD : résumés courts écrits par Claude, pas le texte du livre.

Sheet Questions
A1: # | B1: Topic | C1: Question | D1: Your answer | E1: Status
A2: 1 | B2: Fiche | C2: Base d'attaque : 39 dans le tableau des classes, 49 dans la ligne d'attaque. D'où viennent les 10 de plus ? | D2: Puissance divine : BBA = niveau jusqu'à 20, puis +0,75 par niveau (49 au niveau 59). Ajouté. | E2: answered (round 1)
A3: 2 | B3: Fiche | C3: Points de vie : 2480, puis −915, puis 1665. Que représente −915 ? | D3: Ignoré. | E3: answered (round 1)
A4: 3 | B4: Fiche | C4: Que représentent la ligne « 81 84 44 » et la valeur « 73,5 » à côté de Résistance suprême ? | D4: Totaux des jets de sauvegarde : recalculés dans Danalieth checks (81 / 84 / 44, OK). | E4: answered (round 1)
A5: 4 | B5: Fiche | C5: Ligne « Ward 4 3 » et « 8640 » : à quoi correspondent-ils ? | D5: Ward : 4 utilisations par jour (suivi des utilisations hors périmètre). 8640 ignoré. | E5: answered (round 1)
A6: 5 | B6: Fiche | C6: Caractéristiques : dans quelle colonne va chaque composante (base, race, Démon, Vampire, Dragon, tome, ioun, altération, sorts) ? L'export a perdu les colonnes vides. | D6: Colonnes = types de bonus. Tableau reconstruit dans Danalieth abilities, tous les totaux OK. | E6: answered (round 1)
A7: 6 | B7: Archétypes | C7: Démon, Vampire, Dragon : archétypes officiels (demi-fiélon, vampire, demi-dragon) ou de l'équipe ? Bonus de chacun ? | D7: Archétypes de l'équipe. | E7: answered (round 1)
A8: 7 | B8: Dons | C8: « 5 x spell improvement, caster level +4 » : quel don, quel effet par prise ? | D8: Don cumulable +4 niveau de lanceur, plafonné au niveau de personnage. | E8: answered (round 1)
A9: 8 | B9: Dons | C9: Superspell et Intensify : coût en niveaux d'emplacement, et mode des multiplicateurs (additif ou multiplicatif) ? | D9: Superspell ×4 : +9 ; Intensify ×2 : +6. | E9: answered (round 1)
A10: 9 | B10: Dons | C10: Attaque en puissance et Expertise du combat : valeur fixe à choisir dans l'app, ou description seule ? | D10: Interrupteur avec valeur choisie en début de tour. | E10: answered (round 1)
A11: 10 | B11: Volonté de la mort | C11: Art de la magie +5 / +10 / +20 et niveau de lanceur +3 / +6 / +15 : cumulatifs ou remplacements ? | D11: Remplacement. | E11: answered (round 1)
A12: 11 | B12: Volonté de la mort | C12: Sort épique : un sort connu en plus, ou un emplacement par jour en plus ? | D12: Un emplacement supplémentaire d'un niveau au-dessus du maximum. | E12: answered (round 1)
A13: 12 | B13: Sorts | C13: Moonbow, Météorite, Force du colosse, Force de la nature, Taille de géant, soins (375 et 40/round) : officiels ou de l'équipe ? Effets complets ? | D13: Colosse, Nature, Géant : officiels. Autres : équipe. | E13: answered (round 1)
... A34: 33 | B34: Mage ultime | C34: Niveaux 1 à 10 remplis de mémoire : à vérifier avec votre livre (onglet Progressions, lignes jaunes). | D34: Table du livre fournie, niveaux 1-10 remplis. | E34: answered (round 3)

Sheet Entities
A1: id | B1: type | C1: name_fr | D1: name_en | E1: provenance | F1: source | G1: labels | H1: prerequisite | I1: uses_per_day | J1: description_fr | K1: description_en | L1: status | M1: reviewer_notes
A2: feat.example_feat | B2: feat | C2: Nom français | D2: English name | E2: team | F2: Équipe | G2: melee; epic | H2: level() >= 21 | J2: Description courte en français. | K2: (later) | L2: draft | M2: Ligne d'exemple, ne pas importer
A3: class.warblade | B3: class | C3: Maître des lames | D3: Warblade | E3: official | F3: Book of Nine Swords | G3: melee; maneuvers | J3: Guerrier initiateur de manœuvres martiales ; d12, BBA élevé, Vigueur forte. | L3: draft | M3: Classe de base de Danalieth (niveaux 1-20).
A4: class.wizard | B4: class | C4: Magicien | D4: Wizard | E4: official | F4: SRD | G4: arcane; prepared | J4: Lanceur de sorts profanes préparés, d4. | L4: draft | M4: Mode de sorts : free slots (règle de campagne) ou prepared ? Voir Questions.
A5: class.sorcerer | B5: class | C5: Ensorceleur | D5: Sorcerer | E5: official | F5: SRD | G5: arcane; spontaneous | J5: Lanceur de sorts profanes spontanés, d4. | L5: draft
A6: class.archmage | B6: prestige_class | C6: Archimage | D6: Archmage | E6: official | F6: SRD | G6: arcane; epic-friendly | H6: Art de la magie 15 rangs ; sorts du 7e niveau ; Talent (Art de la magie) ; Science de... (voir SRD) | J6: Classe de prestige des maîtres des arcanes ; chaque niveau donne un pouvoir de Haute arcane. | L6: to confirm | M6: Prérequis exacts à reprendre du SRD lors de l'import.
A7: class.sevenfold_veil | B7: prestige_class | C7: Initié du voile septuple | D7: Initiate of the Sevenfold Veil | E7: official | F7: Complete Arcane | G7: arcane; abjuration | H7: @skill.knowledge_arcana.ranks >= 12 and @skill.knowledge_nature.ranks >= 4 and @skill.spellcraft.ranks >= 12 and has('feat.spell_focus_abjuration') and has('feat.greater_spell_focus_abjuration') and has('feat.skill_focus_spellcraft') | J7: Abjurateur qui tisse des voiles colorés. Dé de vie d4 ; 2 + Int points de compétence. Conditions : Connaissances (mystères) 12 rangs, Connaissances (nature) 4 rangs, Art de la magie 12 rangs, École renforcée et École supérieure (abjuration), Talent (Art de la magie), savoir lancer cinq sorts d'abjuration dont deux du 4e niveau ou plus. | L7: draft | M7: Source : dndtools.net. Condition « cinq sorts d'abjuration » vérifiée à la main.
A8: class.ultimate_magus | B8: prestige_class | C8: Mage ultime | D8: Ultimate Magus | E8: official + team | F8: Complete Mage + Équipe | G8: arcane; dual casting | J8: Combine magie préparée et spontanée, et utilise l'une pour renforcer l'autre. Dé de vie d4 ; 2 + Int points de compétence. Compétences de classe : Concentration, Artisanat, Décryptage, Connaissances (toutes), Profession, Art de la magie, Utilisation d'objets magiques. | L8: draft | M8: Niveaux 1-10 : table du livre (Complete Mage). Niveaux 11-20 : extension de l'équipe.
A9: class.vt_grip_of_death | B9: prestige_class | C9: Émissaire de Von Tarkhein : Poigne de la mort | D9: Emissary of Von Tarkhein: Grip of Death | E9: team | F9: Équipe | G9: death; melee; custom | J9: Voie martiale de l'émissaire : emprise sur la mort, résilience d'outre-tombe, régénération. | L9: draft | M9: Classe épique : BBA et sauvegardes +½ par niveau.
A10: class.vt_will_of_death | B10: prestige_class | C10: Émissaire de Von Tarkhein : Volonté de la mort | D10: Emissary of Von Tarkhein: Will of Death | E10: team | F10: Équipe | G10: death; arcane; custom | J10: Voie arcanique de l'émissaire : sorts épiques et secrets des arcanes. | L10: draft | M10: Classe épique : BBA et sauvegardes +½ par niveau. Danalieth : 3 niveaux.
A11: template.demon | B11: template | C11: Démon | D11: Demon | E11: team | F11: Équipe | G11: template; fiend | J11: Archétype démoniaque. | L11: draft | M11: Archétype de l'équipe. Bonus de caractéristiques repris de la fiche (onglet Danalieth abilities).
A12: template.vampire | B12: template | C12: Vampire | D12: Vampire | E12: team | F12: Équipe | G12: template; undead | J12: Archétype vampirique, avec règles maison (durée, critique, forme de chauve-souris). | L12: draft | M12: Archétype de l'équipe. Bonus de caractéristiques repris de la fiche (onglet Danalieth abilities).
A13: template.dragon | B13: template | C13: Dragon | D13: Dragon | E13: team | F13: Équipe | G13: template; dragon | J13: Archétype draconique. | L13: draft | M13: Archétype de l'équipe. Bonus de caractéristiques repris de la fiche (onglet Danalieth abilities).
A14: feat.spell_focus_abjuration | B14: feat | C14: École renforcée (abjuration) | D14: Spell Focus (abjuration) | E14: official | F14: SRD | G14: magic; DC | J14: +1 au DD des sorts d'abjuration. | L14: draft
A15: feat.greater_spell_focus_abjuration | B15: feat | C15: École supérieure (abjuration) | D15: Greater Spell Focus (abjuration) | E15: official | F15: SRD | G15: magic; DC | H15: has('feat.spell_focus_abjuration') | J15: +1 supplémentaire au DD des sorts d'abjuration. | L15: draft
A16: feat.skill_focus_spellcraft | B16: feat | C16: Talent (Art de la magie) | D16: Skill Focus (Spellcraft) | E16: official | F16: SRD | G16: skill | J16: +3 en Art de la magie. | L16: draft
A17: feat.power_attack | B17: feat | C17: Attaque en puissance | D17: Power Attack | E17: official | F17: SRD | G17: melee | H17: @ability.str.score >= 13 | J17: Échange un malus à l'attaque contre un bonus aux dégâts (double à deux mains). | L17: draft | M17: Interrupteur avec valeur choisie par le joueur en début de tour.
A18: feat.combat_expertise | B18: feat | C18: Expertise du combat | D18: Combat Expertise | E18: official | F18: SRD | G18: melee; defense | H18: @ability.int.score >= 13 | J18: Échange jusqu'à 5 points d'attaque contre la même valeur en CA (esquive). | L18: draft | M18: Interrupteur avec valeur choisie par le joueur en début de tour.
A19: feat.empower_spell | B19: feat | C19: Extension d'effet | D19: Empower Spell | E19: official | F19: SRD | G19: metamagic | J19: Effets numériques ×1,5 ; +2 niveaux d'emplacement. Non cumulable avec Empower, Intensify et Superspell : seul le plus fort s'applique. | L19: draft
A20: feat.quicken_spell | B20: feat | C20: Incantation rapide | D20: Quicken Spell | E20: official | F20: SRD | G20: metamagic | J20: Sort lancé par action rapide ; +4 niveaux. | L20: draft
A21: feat.extend_spell | B21: feat | C21: Extension de durée | D21: Extend Spell | E21: official | F21: SRD | G21: metamagic | J21: Durée ×2 ; +1 niveau. | L21: draft
A22: feat.persistent_spell | B22: feat | C22: Sort persistant | D22: Persistent Spell | E22: official | F22: Complete Arcane | G22: metamagic | J22: Durée portée à 24 heures ; +6 niveaux. | L22: to confirm | M22: Coût +6 d'après le livre ; à confirmer pour votre table.
A23: feat.intensify_spell | B23: feat | C23: Intensification | D23: Intensify Spell | E23: official | F23: Epic (SRD) | G23: metamagic; epic | J23: Effets numériques ×2 ; +6 niveaux d'emplacement (version de la table). Non cumulable avec Empower, Intensify et Superspell : seul le plus fort s'applique. | L23: draft
A24: feat.superspell | B24: feat | C24: Superspell | D24: Superspell | E24: team | F24: Équipe | G24: metamagic; custom | J24: Effets numériques ×4 (y compris les buffs : Force du taureau, Peau d'écorce...) ; +9 niveaux d'emplacement. Non cumulable avec Empower, Intensify et Superspell : seul le plus fort s'applique. | L24: draft
A25: feat.improved_metamagic | B25: feat | C25: Métamagie améliorée | D25: Improved Metamagic | E25: official | F25: Epic (SRD) | G25: metamagic; epic | J25: Réduit de 1 le coût de chaque don de métamagie (minimum +1). | L25: draft | M25: Peut être pris plusieurs fois dans le SRD épique.
A26: feat.improved_spell_capacity | B26: feat | C26: Capacité de sort améliorée | D26: Improved Spell Capacity | E26: official | F26: Epic (SRD) | G26: epic; slots | J26: Un emplacement d'un niveau au-dessus du maximum. Cumulable (×12 pour Danalieth). | L26: draft
A27: feat.spell_improvement | B27: feat | C27: Amélioration du niveau de lanceur | D27: Spell improvement | E27: to confirm | F27: to confirm | G27: epic; caster level | J27: +4 au niveau de lanceur par prise, sans dépasser le niveau de personnage. Cumulable ; sert aux multiclassés pour rattraper leur niveau de lanceur. | L27: draft | M27: Danalieth : 5 prises.
A28: feat.continuum_comprehension | B28: feat | C28: Compréhension du continuum | D28: Continuum Comprehension | E28: team | F28: Équipe | G28: skill; story | J28: +2 en Art de la magie. Obtenu quand le groupe a altéré le monde devant les elfes en lançant 1200 niveaux de sorts. | L28: draft
A29: power.warblade_battle_clarity | B29: class_power | C29: Clarté du combat | D29: Battle Clarity | E29: official | F29: Book of Nine Swords | G29: warblade | J29: Ajoute le modificateur d'Intelligence aux jets de Réflexes. | L29: to confirm | M29: Plafond par niveau de classe dans le livre ; règle maison sans plafond ?
A30: power.warblade_battle_cunning | B30: class_power | C30: Ruse du combat | D30: Battle Cunning | E30: official | F30: Book of Nine Swords + Équipe | G30: warblade | J30: Ajoute le modificateur d'Intelligence aux dégâts (règle maison : toujours, pas seulement contre un adversaire pris au dépourvu). | L30: to confirm
A31: power.warblade_battle_skill | B31: class_power | C31: Talent du combat | D31: Battle Skill | E31: official | F31: Book of Nine Swords | G31: warblade | J31: Ajoute le modificateur d'Intelligence aux tests opposés (bousculade, croc-en-jambe...). | L31: draft
A32: power.archmage_mastery_of_shaping | B32: class_power | C32: Maîtrise de la forme | D32: Mastery of Shaping | E32: official | F32: SRD | G32: archmage; high arcana | J32: Peut créer des espaces non affectés dans les cônes, cylindres, émanations, étendues et rayonnements. | L32: draft | M32: Description seule.
A33: power.archmage_mastery_of_elements | B33: class_power | C33: Maîtrise des énergies | D33: Mastery of Elements | E33: official | F33: SRD | G33: archmage; high arcana | J33: Change le type d'énergie d'un sort (acide, électricité, feu, froid, son). | L33: draft | M33: Description seule.
A34: power.archmage_mastery_of_counterspelling | B34: class_power | C34: Maîtrise des contresorts | D34: Mastery of Counterspelling | E34: official | F34: SRD | G34: archmage; high arcana | J34: Un sort contré est renvoyé au lieu d'être dissipé. | L34: draft | M34: Description seule.
A35: power.archmage_arcane_reach | B35: class_power | C35: Portée profane | D35: Arcane Reach | E35: official | F35: SRD | G35: archmage; high arcana | J35: Les sorts de contact peuvent être lancés à 9 m. | L35: draft | M35: Effet sur spell.range (set 9 m) quand la portée est contact.
A36: power.archmage_spell_power | B36: class_power | C36: Puissance des sorts | D36: Spell Power | E36: official | F36: SRD | G36: archmage; high arcana | J36: +1 niveau de lanceur de sorts. | L36: draft
A37: power.ultimate_magus_caster_level | B37: class_power | C37: Progression du mage ultime | D37: Ultimate Magus caster level | E37: official | F37: Complete Mage | G37: ultimate magus | J37: Fiche : niveau de lanceur +7 ; « Augmented 9 ». | L37: draft | M37: Fiche : « Caster level +7 ». Remplacé par Puissance des sorts profanes (+8 au niveau 20) et la progression des sorts ; à retirer si doublon.
A38: power.vt_grip_of_death | B38: class_power | C38: Emprise de la mort | D38: Grip of Death | E38: team | F38: Équipe | G38: death; aura | J38: Après 1 round d'activation (action libre), aura de 20 m : l'émissaire redirige sur lui 5 % des dégâts subis par ses alliés (10 % au niveau 2, 15 % au niveau 3). Cumulatif avec d'autres effets. | L38: draft
A39: power.vt_beyond_grave_resilience | B39: class_power | C39: Résilience d'outre-tombe | D39: Beyond-the-Grave Resilience | E39: team | F39: Équipe | G39: death; hit points | J39: +500 points de vie au niveau 1, 1000 au niveau 2, 2000 au total au niveau 3. | L39: draft
A40: power.vt_master_of_death | B40: class_power | C40: Maître de la mort | D40: Master of Death | E40: team | F40: Équipe | G40: death; regeneration | J40: Quand Emprise de la mort est active : régénération de 5 % du total de points de vie par round (10 %, puis 15 %). | L40: draft
...

Sheet Effects
A1: entity_id | B1: target | C1: op | D1: value | E1: bonus_type | F1: mult_mode | G1: layer | H1: condition | I1: scope | J1: status | K1: notes
A2: feat.example_feat | B2: ability.str.score | C2: add | D2: 4 | E2: morale | H2: active('toggle.rage') | I2: character | J2: draft | K2: Ligne d'exemple, ne pas importer
A3: feat.spell_focus_abjuration | B3: dc.school[abjuration] | C3: add | D3: 1 | E3: untyped | I3: character | J3: draft
A4: feat.greater_spell_focus_abjuration | B4: dc.school[abjuration] | C4: add | D4: 1 | E4: untyped | I4: character | J4: draft
A5: feat.skill_focus_spellcraft | B5: skill.spellcraft | C5: add | D5: 3 | E5: untyped | I5: character | J5: draft
A6: feat.continuum_comprehension | B6: skill.spellcraft | C6: add | D6: 2 | E6: untyped | I6: character | J6: draft
A7: feat.power_attack | B7: attack.melee | C7: add | D7: -@toggle.power_attack.value | E7: untyped | H7: active('toggle.power_attack') | I7: character | J7: draft | K7: Valeur choisie en début de tour
A8: feat.power_attack | B8: damage.melee | C8: add | D8: @toggle.power_attack.value * 2 | E8: untyped | H8: active('toggle.power_attack') | I8: character | J8: draft | K8: ×2 à deux mains
A9: feat.combat_expertise | B9: attack.melee | C9: add | D9: -@toggle.combat_expertise.value | E9: untyped | H9: active('toggle.combat_expertise') | I9: character | J9: draft | K9: Valeur choisie en début de tour, max 5
A10: feat.combat_expertise | B10: ac.total | C10: add | D10: @toggle.combat_expertise.value | E10: dodge | H10: active('toggle.combat_expertise') | I10: character | J10: draft | K10: Valeur choisie en début de tour, max 5
A11: feat.empower_spell | B11: spell.damage | C11: multiply | D11: 1.5 | F11: exclusive: metamagic_amplify | I11: spell | J11: draft | K11: Seul le plus fort du groupe s'applique
A12: feat.empower_spell | B12: spell.slot_cost | C12: add | D12: 2 | E12: untyped | I12: spell | J12: draft
A13: feat.quicken_spell | B13: spell.action | C13: set | D13: swift | G13: final | I13: spell | J13: draft
A14: feat.quicken_spell | B14: spell.slot_cost | C14: add | D14: 4 | E14: untyped | I14: spell | J14: draft
A15: feat.extend_spell | B15: spell.duration | C15: multiply | D15: 2 | F15: multiplicative | I15: spell | J15: draft
A16: feat.extend_spell | B16: spell.slot_cost | C16: add | D16: 1 | E16: untyped | I16: spell | J16: draft
A17: feat.persistent_spell | B17: spell.duration | C17: set | D17: 24h | G17: final | I17: spell | J17: draft
A18: feat.persistent_spell | B18: spell.slot_cost | C18: add | D18: 6 | E18: untyped | I18: spell | J18: to confirm
A19: feat.intensify_spell | B19: spell.damage | C19: multiply | D19: 2 | F19: exclusive: metamagic_amplify | I19: spell | J19: draft | K19: Seul le plus fort du groupe s'applique
A20: feat.intensify_spell | B20: spell.slot_cost | C20: add | D20: 6 | E20: untyped | I20: spell | J20: draft
A21: feat.superspell | B21: spell.numeric | C21: multiply | D21: 4 | F21: exclusive: metamagic_amplify | I21: spell | J21: draft | K21: Seul le plus fort du groupe s'applique
A22: feat.superspell | B22: spell.slot_cost | C22: add | D22: 9 | E22: untyped | I22: spell | J22: draft
A23: feat.improved_metamagic | B23: spell.slot_cost_per_modifier | C23: add | D23: -1 | E23: untyped | I23: spell | J23: draft | K23: Minimum +1 par modificateur
A24: feat.improved_spell_capacity | B24: slots.above_max | C24: add | D24: 1 | E24: untyped | I24: character | J24: draft | K24: Un emplacement au-dessus du maximum, par prise (×12)
A25: power.warblade_battle_clarity | B25: save.ref | C25: add | D25: @ability.int.mod | E25: untyped | I25: character | J25: to confirm | K25: Plafond ?
A26: power.warblade_battle_cunning | B26: damage.melee | C26: add | D26: @ability.int.mod | E26: untyped | I26: character | J26: draft
A27: power.warblade_battle_skill | B27: check.opposed | C27: add | D27: @ability.int.mod | E27: untyped | I27: character | J27: draft
A28: power.archmage_arcane_reach | B28: spell.range | C28: set | D28: 9 m | G28: final | H28: spell.range == 'touch' | I28: spell | J28: draft
A29: power.archmage_spell_power | B29: caster_level.arcane | C29: add | D29: 1 | E29: untyped | I29: character | J29: draft
A30: power.ultimate_magus_caster_level | B30: caster_level.arcane | C30: add | D30: 7 | E30: untyped | I30: character | J30: to confirm
A31: power.vt_beyond_grave_resilience | B31: hp.max | C31: add | D31: if(level('class.vt_grip_of_death') >= 7, 2000, if(level('class.vt_grip_of_death') >= 4, 1000, 500)) | E31: untyped | I31: character | J31: draft | K31: Paliers niveau 1 / 4 / 7 de la classe
A32: power.vt_master_of_death | B32: hp.regeneration | C32: add | D32: floor(@hp.max * if(level('class.vt_grip_of_death') >= 8, 15, if(level('class.vt_grip_of_death') >= 5, 10, 5)) / 100) | E32: untyped | H32: active('toggle.vt_grip_of_death') | I32: character | J32: draft
A33: power.vt_grip_of_death | B33: aura.damage_redirect_pct | C33: add | D33: if(level('class.vt_grip_of_death') >= 10, 15, if(level('class.vt_grip_of_death') >= 6, 10, 5)) | E33: untyped | H33: active('toggle.vt_grip_of_death') | I33: character | J33: draft | K33: Cumulatif avec d'autres effets
A34: power.vt_arcane_secret_spellcraft | B34: skill.spellcraft | C34: add | D34: if(level('class.vt_will_of_death') >= 7, 20, if(level('class.vt_will_of_death') >= 4, 10, 5)) | E34: untyped | I34: character | J34: draft | K34: Remplacement : 5, puis 10, puis 20
A35: class.vt_will_of_death | B35: caster_level.arcane | C35: add | D35: if(level('class.vt_will_of_death') >= 10, 15, if(level('class.vt_will_of_death') >= 5, 6, 3)) | E35: untyped | I35: character | J35: draft | K35: Remplacement : 3, puis 6, puis 15
A36: power.vt_mortis_incantatum | B36: spell.caster_level_vs_sr | C36: add | D36: 10 | E36: untyped | I36: spell | J36: draft
A37: power.vt_mortis_incantatum | B37: spell.dc | C37: add | D37: 10 | E37: untyped | I37: spell | J37: draft
A38: power.vt_primum_incantatum | B38: spell.damage | C38: multiply | D38: 3 | F38: multiplicative | I38: spell | J38: draft
A39: power.vt_primum_incantatum | B39: spell.healing | C39: multiply | D39: 2 | F39: multiplicative | I39: spell | J39: draft
A40: power.vt_primum_incantatum | B40: spell.duration | C40: multiply | D40: 2 | F40: multiplicative | I40: spell | J40: draft
...

Sheet Progressions
A1: class_id | B1: level | C1: bab | D1: fort | E1: ref | F1: will | G1: grants | H1: status | I1: notes
A2: class.vt_grip_of_death | B2: 1 | C2: +0.5 | D2: +0.5 | E2: +0.5 | F2: +0.5 | G2: power.vt_grip_of_death (1) | H2: draft | I2: Classe épique : +½ par niveau
A3: class.vt_grip_of_death | B3: 2 | C3: +0.5 | D3: +0.5 | E3: +0.5 | F3: +0.5 | G3: power.vt_beyond_grave_resilience (1) | H3: draft | I3: Classe épique : +½ par niveau
A4: class.vt_grip_of_death | B4: 3 | C4: +0.5 | D4: +0.5 | E4: +0.5 | F4: +0.5 | G4: power.vt_master_of_death (1) | H4: draft | I4: Classe épique : +½ par niveau
A5: class.vt_grip_of_death | B5: 4 | C5: +0.5 | D5: +0.5 | E5: +0.5 | F5: +0.5 | G5: power.vt_beyond_grave_resilience (2) | H5: draft | I5: Classe épique : +½ par niveau
A6: class.vt_grip_of_death | B6: 5 | C6: +0.5 | D6: +0.5 | E6: +0.5 | F6: +0.5 | G6: power.vt_master_of_death (2) | H6: draft | I6: Classe épique : +½ par niveau
A7: class.vt_grip_of_death | B7: 6 | C7: +0.5 | D7: +0.5 | E7: +0.5 | F7: +0.5 | G7: power.vt_grip_of_death (2) | H7: draft | I7: Classe épique : +½ par niveau
A8: class.vt_grip_of_death | B8: 7 | C8: +0.5 | D8: +0.5 | E8: +0.5 | F8: +0.5 | G8: power.vt_beyond_grave_resilience (3) | H8: draft | I8: Classe épique : +½ par niveau
A9: class.vt_grip_of_death | B9: 8 | C9: +0.5 | D9: +0.5 | E9: +0.5 | F9: +0.5 | G9: power.vt_master_of_death (3) | H9: draft | I9: Classe épique : +½ par niveau
A10: class.vt_grip_of_death | B10: 9 | C10: +0.5 | D10: +0.5 | E10: +0.5 | F10: +0.5 | G10: bonus feat | H10: draft | I10: Classe épique : +½ par niveau
A11: class.vt_grip_of_death | B11: 10 | C11: +0.5 | D11: +0.5 | E11: +0.5 | F11: +0.5 | G11: power.vt_grip_of_death (3) | H11: draft | I11: Classe épique : +½ par niveau
A12: class.vt_will_of_death | B12: 1 | C12: +0.5 | D12: +0.5 | E12: +0.5 | F12: +0.5 | G12: caster level 3; power.vt_epic_spell | H12: draft | I12: Classe épique : +½ par niveau
A13: class.vt_will_of_death | B13: 2 | C13: +0.5 | D13: +0.5 | E13: +0.5 | F13: +0.5 | G13: power.vt_arcane_secret_spellcraft (+5) | H13: draft | I13: Classe épique : +½ par niveau
... A19: class.vt_will_of_death | B19: 8 | C19: +0.5 | D19: +0.5 | E19: +0.5 | F19: +0.5 | G19: power.vt_epic_spell | H19: draft | I19: Classe épique : +½ par niveau
A20: class.vt_will_of_death | B20: 9 | C20: +0.5 | D20: +0.5 | E20: +0.5 | F20: +0.5 | H20: draft | I20: Classe épique : +½ par niveau
A21: class.vt_will_of_death | B21: 10 | C21: +0.5 | D21: +0.5 | E21: +0.5 | F21: +0.5 | G21: caster level 15 (replaces 6); power.vt_epic_spell; power.vt_infinitum_incantatum | H21: draft | I21: Classe épique : +½ par niveau
A22: class.warblade | B22: 1 | C22: 1 | D22: 2 | E22: 0 | F22: 0 | G22: maneuvers; weapon aptitude | H22: to confirm | I22: Capacités d'après le livre, à vérifier
A23: class.warblade | B23: 2 | C23: 2 | D23: 3 | E23: 0 | F23: 0 | G23: power.warblade_battle_clarity; power.warblade_uncanny_dodge | H23: to confirm | I23: Capacités d'après le livre, à vérifier
A24: class.warblade | B24: 3 | C24: 3 | D24: 3 | E24: 1 | F24: 1 | H24: draft
A25: class.warblade | B25: 4 | C25: 4 | D25: 4 | E25: 1 | F25: 1 | H25: draft
A26: class.warblade | B26: 5 | C26: 5 | D26: 4 | E26: 1 | F26: 1 | G26: bonus feat | H26: to confirm | I26: Capacités d'après le livre, à vérifier
A27: class.warblade | B27: 6 | C27: 6 | D27: 5 | E27: 2 | F27: 2 | H27: draft
A28: class.warblade | B28: 7 | C28: 7 | D28: 5 | E28: 2 | F28: 2 | G28: battle ardor | H28: to confirm | I28: Capacités d'après le livre, à vérifier
A29: class.warblade | B29: 8 | C29: 8 | D29: 6 | E29: 2 | F29: 2 | H29: draft
A30: class.warblade | B30: 9 | C30: 9 | D30: 6 | E30: 3 | F30: 3 | G30: bonus feat; improved uncanny dodge | H30: to confirm | I30: Capacités d'après le livre, à vérifier
A31: class.warblade | B31: 10 | C31: 10 | D31: 7 | E31: 3 | F31: 3 | H31: draft
A32: class.warblade | B32: 11 | C32: 11 | D32: 7 | E32: 3 | F32: 3 | G32: power.warblade_battle_cunning | H32: to confirm | I32: Capacités d'après le livre, à vérifier
A33: class.warblade | B33: 12 | C33: 12 | D33: 8 | E33: 4 | F33: 4 | H33: draft
A34: class.warblade | B34: 13 | C34: 13 | D34: 8 | E34: 4 | F34: 4 | G34: bonus feat | H34: to confirm | I34: Capacités d'après le livre, à vérifier
A35: class.warblade | B35: 14 | C35: 14 | D35: 9 | E35: 4 | F35: 4 | H35: draft
A36: class.warblade | B36: 15 | C36: 15 | D36: 9 | E36: 5 | F36: 5 | G36: power.warblade_battle_skill | H36: to confirm | I36: Capacités d'après le livre, à vérifier
A37: class.warblade | B37: 16 | C37: 16 | D37: 10 | E37: 5 | F37: 5 | H37: draft
A38: class.warblade | B38: 17 | C38: 17 | D38: 10 | E38: 5 | F38: 5 | G38: bonus feat | H38: to confirm | I38: Capacités d'après le livre, à vérifier
A39: class.warblade | B39: 18 | C39: 18 | D39: 11 | E39: 6 | F39: 6 | H39: draft
A40: class.warblade | B40: 19 | C40: 19 | D40: 11 | E40: 6 | F40: 6 | G40: battle mastery | H40: to confirm | I40: Capacités d'après le livre, à vérifier
A41: class.warblade | B41: 20 | C41: 20 | D41: 12 | E41: 6 | F41: 6 | H41: draft
A42: rule.epic | B42: each level after 20 | C42: +0.5 | D42: +0.5 | E42: +0.5 | F42: +0.5 | G42: Règle maison : BBA et sauvegardes +½ par niveau épique, additionnés en fractions, arrondis une fois | H42: draft | I42: Retrouvé sur la fiche : total 39 / 29 / 35 / 29
A43: rule.hit_points | B43: each level | G43: Points de vie par niveau = ¾ du dé de vie (d12 → 9, d4 → 3) | H43: draft | I43: Retrouvé sur la fiche : 297 PV de base
A44: rule.experience | B44: level n | G44: XP requis = n × (n − 1) / 2 × 1000 | H44: draft | I44: 1 718 250 XP → niveau 59
A45: class.ultimate_magus | B45: 1 | C45: 0 | D45: 0 | E45: 0 | F45: 2 | G45: power.ultimate_magus_arcane_spell_power (+1); spellcasting: +1 level of lowest-caster-level arcane class | H45: draft | I45: Table du livre. Pris après le niveau 20 de personnage : BBA et sauvegardes suivent la règle épique (+½).
...

Sheet Relations
A1: from_id | B1: relation | C1: to_id | D1: level | E1: notes
A2: class.archmage | B2: grants | C2: power.archmage_mastery_of_shaping | E2: Choix de haute arcane
A3: class.archmage | B3: grants | C3: power.archmage_mastery_of_elements | E3: Choix de haute arcane
A4: class.archmage | B4: grants | C4: power.archmage_mastery_of_counterspelling | E4: Choix de haute arcane
A5: class.archmage | B5: grants | C5: power.archmage_arcane_reach | E5: Choix de haute arcane
A6: class.archmage | B6: grants | C6: power.archmage_spell_power | E6: Choix de haute arcane
A7: class.ultimate_magus | B7: grants | C7: power.ultimate_magus_caster_level
A8: template.vampire | B8: grants | C8: power.vampire_bat_form
A9: template.vampire | B9: grants | C9: power.vampire_house_rules
A10: feat.greater_spell_focus_abjuration | B10: requires | C10: feat.spell_focus_abjuration
A11: spell.bulls_strength | B11: on_spell_list | C11: class.wizard | D11: 2 | E11: SRD
A12: spell.bulls_strength | B12: on_spell_list | C12: class.sorcerer | D12: 2 | E12: SRD
A13: spell.bears_endurance | B13: on_spell_list | C13: class.wizard | D13: 2 | E13: SRD
A14: spell.foxs_cunning | B14: on_spell_list | C14: class.wizard | D14: 2 | E14: SRD
A15: spell.barkskin | B15: on_spell_list | C15: class.wizard | E15: to confirm : sort de druide/rôdeur dans le SRD, pas de magicien
A16: spell.divine_favor | B16: on_spell_list | C16: class.wizard | E16: to confirm : sort de prêtre/paladin dans le SRD
A17: spell.protection_from_evil | B17: on_spell_list | C17: class.wizard | D17: 1 | E17: SRD
A18: class.ultimate_magus | B18: grants | C18: power.ultimate_magus_augmented_casting_superior | D18: 20 | E18: Extension de l'équipe
A19: class.warblade | B19: grants | C19: power.warblade_uncanny_dodge | D19: 2
A20: spell.divine_power | B20: on_spell_list | C20: class.wizard | E20: to confirm : sort de prêtre dans le SRD
A21: spell.spell_resistance | B21: on_spell_list | C21: class.wizard | E21: to confirm : sort de prêtre dans le SRD
A22: class.sevenfold_veil | B22: grants | C22: power.sv_warding
A23: class.sevenfold_veil | B23: grants | C23: power.sv_unimpeachable_abjuration
A24: class.sevenfold_veil | B24: grants | C24: power.sv_unanswerable_strike
A25: class.sevenfold_veil | B25: grants | C25: power.sv_reactive_warding
A26: class.sevenfold_veil | B26: grants | C26: power.sv_double_warding
A27: class.sevenfold_veil | B27: grants | C27: power.sv_kaleidoscopic_doom
A28: class.sevenfold_veil | B28: grants | C28: power.sv_veil_red
A29: class.sevenfold_veil | B29: grants | C29: power.sv_veil_orange
A30: class.sevenfold_veil | B30: grants | C30: power.sv_veil_yellow
A31: class.sevenfold_veil | B31: grants | C31: power.sv_veil_green
A32: class.sevenfold_veil | B32: grants | C32: power.sv_veil_blue
A33: class.sevenfold_veil | B33: grants | C33: power.sv_veil_indigo
A34: class.sevenfold_veil | B34: grants | C34: power.sv_veil_violet
A35: spell.moonbow | B35: on_spell_list | C35: class.wizard | D35: 9 | E35: to confirm : liste supposée
A36: spell.moonbow | B36: on_spell_list | C36: class.sorcerer | D36: 9 | E36: to confirm : liste supposée
A37: spell.meteorite | B37: on_spell_list | C37: class.wizard | D37: 9 | E37: to confirm : liste supposée
A38: spell.meteorite | B38: on_spell_list | C38: class.sorcerer | D38: 9 | E38: to confirm : liste supposée

Sheet Danalieth abilities
A1: Ability | B1: Base | C1: Race | D1: Level | E1: Demon | F1: Vampire | G1: Dragon | H1: Tome | I1: Ioun | J1: Enhancement (spell) | K1: Force of the colossus | L1: Force of nature | M1: Giant size | N1: Total | O1: Modifier | P1: Sheet total | Q1: Check
A2: Strength | B2: 18 | F2: 8 | G2: 2 | H2: 5 | I2: 2 | J2: 16 | K2: 12 | L2: 16 | M2: 32 | N2: =SUM(B2:M2) -> 111 | O2: =ROUNDDOWN((N2-10)/2,0) -> 50 | P2: 111 | Q2: =IF(N2=P2,"OK","MISMATCH") -> OK
A3: Dexterity | B3: 16 | G3: 2 | I3: 2 | L3: 16 | N3: =SUM(B3:M3) -> 36 | O3: =ROUNDDOWN((N3-10)/2,0) -> 13 | P3: 36 | Q3: =IF(N3=P3,"OK","MISMATCH") -> OK
A4: Constitution | B4: 16 | F4: 6 | G4: 2 | H4: 5 | I4: 2 | J4: 16 | K4: 6 | L4: 16 | M4: 16 | N4: =SUM(B4:M4) -> 85 | O4: =ROUNDDOWN((N4-10)/2,0) -> 37 | P4: 85 | Q4: =IF(N4=P4,"OK","MISMATCH") -> OK
A5: Intelligence | B5: 18 | C5: 2 | D5: 14 | E5: 2 | F5: 4 | G5: 2 | H5: 5 | I5: 2 | J5: 16 | N5: =SUM(B5:M5) -> 65 | O5: =ROUNDDOWN((N5-10)/2,0) -> 27 | P5: 65 | Q5: =IF(N5=P5,"OK","MISMATCH") -> OK
A6: Wisdom | B6: 12 | G6: 2 | I6: 2 | N6: =SUM(B6:M6) -> 16 | O6: =ROUNDDOWN((N6-10)/2,0) -> 3 | P6: 16 | Q6: =IF(N6=P6,"OK","MISMATCH") -> OK
A7: Charisma | B7: 12 | C7: -2 | F7: 2 | G7: 2 | H7: 5 | I7: 2 | N7: =SUM(B7:M7) -> 21 | O7: =ROUNDDOWN((N7-10)/2,0) -> 5 | P7: 21 | Q7: =IF(N7=P7,"OK","MISMATCH") -> OK
A9: Enhancement column: Bull's Strength, Bear's Endurance, Fox's Cunning (+4 × 4 with Superspell). Each column is one bonus type. Blue = values from the sheet; black = formulas.

Sheet Danalieth checks
A1: Value | B1: Component 1 | C1: Component 2 | D1: Component 3 | E1: Component 4 | F1: Component 5 | G1: Component 6 | H1: Component 7 | I1: Computed | J1: Sheet | K1: Check | L1: How
A2: Character level | B2: 20 | C2: 3 | D2: 1 | E2: 5 | F2: 7 | G2: 20 | H2: 3 | I2: =SUM(B2:H2) -> 59 | J2: 59 | K2: =IF(I2=J2,"OK","MISMATCH") -> OK | L2: Warblade, Wizard, Sorcerer, Archmage, Sevenfold Veil, Ultimate Magus, Will of Death
A3: Base attack (classes) | B3: 20 | C3: 1.5 | D3: 0.5 | E3: 2.5 | F3: 3.5 | G3: 10 | H3: 1.5 | I3: =ROUNDDOWN(SUM(B3:H3),0) -> 39 | J3: 39 | K3: =IF(I3=J3,"OK","MISMATCH") -> OK | L3: 20 + ½ par niveau épique, arrondi une fois
A4: Base attack (Divine Power) | B4: =I2 -> 59 | C4: 20 | D4: 0.75 | I4: =C4+ROUNDDOWN(D4*(B4-20),0) -> 49 | J4: 49 | K4: =IF(I4=J4,"OK","MISMATCH") -> OK | L4: 20 + 0,75 par niveau au-delà de 20
A5: Reflex (class) | B5: 6 | C5: 1.5 | D5: 0.5 | E5: 2.5 | F5: 3.5 | G5: 10 | H5: =1.5+3.5 -> 5 | I5: =ROUNDDOWN(SUM(B5:H5),0) -> 29 | J5: 29 | K5: =IF(I5=J5,"OK","MISMATCH") -> OK | L5: Volonté de la mort : 1,5 (épique) + 3,5 (Résistance de l'émissaire)
A6: Fortitude (class) | B6: 12 | C6: 1.5 | D6: 0.5 | E6: 2.5 | F6: 3.5 | G6: 10 | H6: =1.5+3.5 -> 5 | I6: =ROUNDDOWN(SUM(B6:H6),0) -> 35 | J6: 35 | K6: =IF(I6=J6,"OK","MISMATCH") -> OK | L6: Volonté de la mort : 1,5 (épique) + 3,5 (Résistance de l'émissaire)
A7: Will (class) | B7: 6 | C7: 1.5 | D7: 0.5 | E7: 2.5 | F7: 3.5 | G7: 10 | H7: =1.5+3.5 -> 5 | I7: =ROUNDDOWN(SUM(B7:H7),0) -> 29 | J7: 29 | K7: =IF(I7=J7,"OK","MISMATCH") -> OK | L7: Volonté de la mort : 1,5 (épique) + 3,5 (Résistance de l'émissaire)
A8: Reflex (total) | B8: =I5 -> 29 | C8: ='Danalieth abilities'!O3 -> 13 | D8: ='Danalieth abilities'!O5 -> 27 | E8: 12 | I8: =SUM(B8:E8) -> 81 | J8: 81 | K8: =IF(I8=J8,"OK","MISMATCH") -> OK | L8: Classes + Dex + Int (Clarté du combat) + cape
A9: Fortitude (total) | B9: =I6 -> 35 | C9: ='Danalieth abilities'!O4 -> 37 | D9: 12 | I9: =SUM(B9:D9) -> 84 | J9: 84 | K9: =IF(I9=J9,"OK","MISMATCH") -> OK | L9: Classes + Con + cape
A10: Will (total) | B10: =I7 -> 29 | C10: ='Danalieth abilities'!O6 -> 3 | D10: 12 | I10: =SUM(B10:D10) -> 44 | J10: 44 | K10: =IF(I10=J10,"OK","MISMATCH") -> OK | L10: Classes + Sag + cape
A11: Base hit points | B11: 180 | C11: 9 | D11: 3 | E11: 15 | F11: 21 | G11: 60 | H11: 9 | I11: =SUM(B11:H11) -> 297 | J11: 297 | K11: =IF(I11=J11,"OK","MISMATCH") -> OK | L11: ¾ du dé de vie par niveau
A12: Total hit points | B12: =I11 -> 297 | C12: ='Danalieth abilities'!O4 -> 37 | D12: =I2 -> 59 | I12: =B12+C12*D12 -> 2480 | J12: 2480 | K12: =IF(I12=J12,"OK","MISMATCH") -> OK | L12: Base + mod. Con × niveau
A13: Melee attack | B13: =I4 -> 49 | C13: 24 | D13: 12 | E13: 10 | F13: ='Danalieth abilities'!O2 -> 50 | I13: =SUM(B13:F13) -> 145 | J13: 145 | K13: =IF(I13=J13,"OK","MISMATCH") -> OK | L13: BBA (Puissance divine) + Faveur divine + arme + posture + mod. Force
A14: Melee damage | B14: =ROUNDDOWN(3*3.5,0) -> 10 | C14: 12 | D14: =ROUNDDOWN('Danalieth abilities'!O2*1.5,0) -> 75 | E14: 24 | F14: ='Danalieth abilities'!O5 -> 27 | I14: =SUM(B14:F14) -> 148 | J14: 148 | K14: =IF(I14=J14,"OK","MISMATCH") -> OK | L14: Arme 3d6 (taille G, moyenne 10) + altération + Force × 1,5 + Faveur divine + mod. Int
A15: Spell resistance | B15: 12 | C15: 60 | I15: =B15+C15 -> 72 | J15: 72 | K15: =IF(I15=J15,"OK","MISMATCH") -> OK | L15: Résistance à la magie : 12 + niveau de lanceur
A16: Level from XP | B16: 1718250 | I16: =ROUNDDOWN((1+SQRT(1+8*B16/1000))/2,0) -> 59 | J16: 59 | K16: =IF(I16=J16,"OK","MISMATCH") -> OK | L16: n × (n − 1) / 2 × 1000 ≤ XP
A18: Blue = numbers from the sheet; black = formulas (modifiers come from the Danalieth abilities tab). Check must read OK on every row.
